<?xml version="1.0"?>

<robot
    xmlns:sensor="http://playerstage.sourceforge.net/gazebo/xmlschema/#sensor"
    xmlns:controller="http://playerstage.sourceforge.net/gazebo/xmlschema/#controller"
    xmlns:interface="http://playerstage.sourceforge.net/gazebo/xmlschema/#interface">
    
    <!-- Properties (Constants) -->
    <property name="M_PI" value="3.14159"/>
    
    <macro name="tilt_laser" params="parent x y z">
        <joint name="${parent}_platform_joint" type="fixed">
            <origin xyz="${x} ${y} ${z}" rpy="0 0 0" />
            <parent link="${parent}" />
            <child link="${parent}_motor_link" />
        </joint>
        
        <link name="${parent}_motor_link">
            <inertial>
                <mass value="0.1" />
                <origin xyz=" 0 0 0 " />
                <inertia  ixx="0.012411765597" ixy="0.0" ixz="0.0"
                          iyy="0.015218160428" iyz="0.0"
                          izz="0.011763977943" />
            </inertial>
            
            <visual>
                <origin xyz="0 0 0" rpy="${M_PI/2} 0 0" />
                <geometry>
                    <cylinder radius="0.009" length="0.002" />
                </geometry>
            </visual>
            
            <collision>
                <origin xyz="0 0 0" rpy="${M_PI/2} 0 0" />
                <geometry>
                    <cylinder radius="0.009" length="0.002" />
                </geometry>
            </collision>
        </link>

        <joint name="${parent}_tilt_laser_joint" type="continuous">
            <origin xyz="0 0 0" rpy="0 0 0" />
            <axis xyz="0 1 0" />
            <anchor xyz="0 0 0" />
            <limit effort="100" velocity="100" />
            <joint_properties damping="0.0" friction="0.0" />
            <parent link="${parent}_motor_link" />
            <child link="${parent}_platform_link" />
        </joint>
        
        <link name="${parent}_platform_link">
            <inertial>
                <mass value="5" />
                <origin xyz=" 0 -0.008 0 " />
                <inertia  ixx="0.012411765597" ixy="0.0" ixz="0.0"
                          iyy="0.015218160428" iyz="0.0"
                          izz="0.011763977943" />
            </inertial>
            
            <visual>
                <origin xyz="0 -0.008 0" rpy="${M_PI/2} 0 0" />
                <geometry>
                    <box size="0.01 0.01 0.01" />
                </geometry>
                <material name="White" />
            </visual>
            
            <collision>
                <origin xyz="0 -0.008 0" rpy="${M_PI/2} 0 0" />
                <geometry>
                    <box size="0.01 0.01 0.01" />
                </geometry>
            </collision>
        </link>

        <gazebo reference="${parent}_platform_link" >
            <elem key="mu1" value="50.0" />
            <elem key="mu2" value="50.0" />
            <elem key="kp"  value="100000000.0" />
            <elem key="kd"  value="1.0" />
            <material>Create/Green</material>
        </gazebo>

        <gazebo reference="${parent}_motor_link" >
            <material>Create/White</material>
        </gazebo>

        <transmission type="pr2_mechanism_model/SimpleTransmission" name="${parent}_platform_trans">
            <actuator name="${parent}_platform_motor" />
            <joint name="${parent}_tilt_laser_joint" />
            <mechanicalReduction>1.0</mechanicalReduction>
        </transmission>

        <gazebo reference="${parent}_platform_link">
          <sensor:ray name="tilt_laser">
            <resRange>0.1</resRange>
            <rayCount>320</rayCount>
            <rangeCount>320</rangeCount>
            <laserCount>1</laserCount>
            <origin>0.0 0.0 0.0</origin>
            <displayRays>true</displayRays>
            
            <minAngle>-50</minAngle> <!-- scans own arms if -135~+135 -->
            <maxAngle>50</maxAngle>
            
            <minRange>0.02</minRange>
            <maxRange>10.0</maxRange>
            <updateRate>20.0</updateRate>
            <controller:gazebo_ros_laser name="gazebo_ros_tilt_laser_link_controller" plugin="libgazebo_ros_laser.so">
              <gaussianNoise>0.005</gaussianNoise>
              <alwaysOn>true</alwaysOn>
              <updateRate>20.0</updateRate>
              <topicName>tilt_scan</topicName>
              <frameName>${parent}_platform_link</frameName>
              <interface:laser name="gazebo_ros_tilt_laser_link_iface"/>
            </controller:gazebo_ros_laser>
          </sensor:ray>
          <material>Gazebo/Red</material>
        </gazebo>
    </macro>
</robot>

